2025-05-05 12:12:35,771 ERROR: Exception on /favicon.ico [GET] [in /opt/sidney/venv/lib/python3.12/site-packages/flask/app.py:1414]
Traceback (most recent call last):
  File "/opt/sidney/venv/lib/python3.12/site-packages/flask/app.py", line 1484, in full_dispatch_request
    rv = self.dispatch_request()
         ^^^^^^^^^^^^^^^^^^^^^^^
  File "/opt/sidney/venv/lib/python3.12/site-packages/flask/app.py", line 1458, in dispatch_request
    self.raise_routing_exception(req)
  File "/opt/sidney/venv/lib/python3.12/site-packages/flask/app.py", line 1440, in raise_routing_exception
    raise request.routing_exception  # type: ignore
    ^^^^^^^^^^^^^^^^^^^^^^^^^^^^^^^
  File "/opt/sidney/venv/lib/python3.12/site-packages/flask/ctx.py", line 353, in match_request
    result = self.url_adapter.match(return_rule=True)  # type: ignore
             ^^^^^^^^^^^^^^^^^^^^^^^^^^^^^^^^^^^^^^^^
  File "/opt/sidney/venv/lib/python3.12/site-packages/werkzeug/routing/map.py", line 655, in match
    raise NotFound() from None
werkzeug.exceptions.NotFound: 404 Not Found: The requested URL was not found on the server. If you entered the URL manually please check your spelling and try again.

During handling of the above exception, another exception occurred:

Traceback (most recent call last):
  File "/opt/sidney/venv/lib/python3.12/site-packages/sqlalchemy/engine/base.py", line 1965, in _exec_single_context
    self.dialect.do_execute(
  File "/opt/sidney/venv/lib/python3.12/site-packages/sqlalchemy/engine/default.py", line 921, in do_execute
    cursor.execute(statement, parameters)
sqlite3.OperationalError: no such table: web_users

The above exception was the direct cause of the following exception:

Traceback (most recent call last):
  File "/opt/sidney/venv/lib/python3.12/site-packages/flask/app.py", line 2190, in wsgi_app
    response = self.full_dispatch_request()
               ^^^^^^^^^^^^^^^^^^^^^^^^^^^^
  File "/opt/sidney/venv/lib/python3.12/site-packages/flask/app.py", line 1486, in full_dispatch_request
    rv = self.handle_user_exception(e)
         ^^^^^^^^^^^^^^^^^^^^^^^^^^^^^
  File "/opt/sidney/venv/lib/python3.12/site-packages/flask/app.py", line 1341, in handle_user_exception
    return self.handle_http_exception(e)
           ^^^^^^^^^^^^^^^^^^^^^^^^^^^^^
  File "/opt/sidney/venv/lib/python3.12/site-packages/flask/app.py", line 1281, in handle_http_exception
    return self.ensure_sync(handler)(e)
           ^^^^^^^^^^^^^^^^^^^^^^^^^^^^
  File "/opt/sidney/app/errors.py", line 6, in not_found_error
    return render_template('errors/404.html'), 404
           ^^^^^^^^^^^^^^^^^^^^^^^^^^^^^^^^^^
  File "/opt/sidney/venv/lib/python3.12/site-packages/flask/templating.py", line 151, in render_template
    return _render(app, template, context)
           ^^^^^^^^^^^^^^^^^^^^^^^^^^^^^^^
  File "/opt/sidney/venv/lib/python3.12/site-packages/flask/templating.py", line 128, in _render
    app.update_template_context(context)
  File "/opt/sidney/venv/lib/python3.12/site-packages/flask/app.py", line 737, in update_template_context
    context.update(func())
                   ^^^^^^
  File "/opt/sidney/venv/lib/python3.12/site-packages/flask_login/utils.py", line 407, in _user_context_processor
    return dict(current_user=_get_user())
                             ^^^^^^^^^^^
  File "/opt/sidney/venv/lib/python3.12/site-packages/flask_login/utils.py", line 372, in _get_user
    current_app.login_manager._load_user()
  File "/opt/sidney/venv/lib/python3.12/site-packages/flask_login/login_manager.py", line 364, in _load_user
    user = self._user_callback(user_id)
           ^^^^^^^^^^^^^^^^^^^^^^^^^^^^
  File "/opt/sidney/app/__init__.py", line 50, in load_user
    return User.query.get(int(user_id))
           ^^^^^^^^^^^^^^^^^^^^^^^^^^^^
  File "<string>", line 2, in get
  File "/opt/sidney/venv/lib/python3.12/site-packages/sqlalchemy/util/deprecations.py", line 386, in warned
    return fn(*args, **kwargs)  # type: ignore[no-any-return]
           ^^^^^^^^^^^^^^^^^^^
  File "/opt/sidney/venv/lib/python3.12/site-packages/sqlalchemy/orm/query.py", line 1131, in get
    return self._get_impl(ident, loading.load_on_pk_identity)
           ^^^^^^^^^^^^^^^^^^^^^^^^^^^^^^^^^^^^^^^^^^^^^^^^^^
  File "/opt/sidney/venv/lib/python3.12/site-packages/sqlalchemy/orm/query.py", line 1140, in _get_impl
    return self.session._get_impl(
           ^^^^^^^^^^^^^^^^^^^^^^^
  File "/opt/sidney/venv/lib/python3.12/site-packages/sqlalchemy/orm/session.py", line 3700, in _get_impl
    return db_load_fn(
           ^^^^^^^^^^^
  File "/opt/sidney/venv/lib/python3.12/site-packages/sqlalchemy/orm/loading.py", line 666, in load_on_pk_identity
    session.execute(
  File "/opt/sidney/venv/lib/python3.12/site-packages/sqlalchemy/orm/session.py", line 2262, in execute
    return self._execute_internal(
           ^^^^^^^^^^^^^^^^^^^^^^^
  File "/opt/sidney/venv/lib/python3.12/site-packages/sqlalchemy/orm/session.py", line 2144, in _execute_internal
    result: Result[Any] = compile_state_cls.orm_execute_statement(
                          ^^^^^^^^^^^^^^^^^^^^^^^^^^^^^^^^^^^^^^^^
  File "/opt/sidney/venv/lib/python3.12/site-packages/sqlalchemy/orm/context.py", line 293, in orm_execute_statement
    result = conn.execute(
             ^^^^^^^^^^^^^
  File "/opt/sidney/venv/lib/python3.12/site-packages/sqlalchemy/engine/base.py", line 1412, in execute
    return meth(
           ^^^^^
  File "/opt/sidney/venv/lib/python3.12/site-packages/sqlalchemy/sql/elements.py", line 515, in _execute_on_connection
    return connection._execute_clauseelement(
           ^^^^^^^^^^^^^^^^^^^^^^^^^^^^^^^^^^
  File "/opt/sidney/venv/lib/python3.12/site-packages/sqlalchemy/engine/base.py", line 1635, in _execute_clauseelement
    ret = self._execute_context(
          ^^^^^^^^^^^^^^^^^^^^^^
  File "/opt/sidney/venv/lib/python3.12/site-packages/sqlalchemy/engine/base.py", line 1844, in _execute_context
    return self._exec_single_context(
           ^^^^^^^^^^^^^^^^^^^^^^^^^^
  File "/opt/sidney/venv/lib/python3.12/site-packages/sqlalchemy/engine/base.py", line 1984, in _exec_single_context
    self._handle_dbapi_exception(
  File "/opt/sidney/venv/lib/python3.12/site-packages/sqlalchemy/engine/base.py", line 2339, in _handle_dbapi_exception
    raise sqlalchemy_exception.with_traceback(exc_info[2]) from e
  File "/opt/sidney/venv/lib/python3.12/site-packages/sqlalchemy/engine/base.py", line 1965, in _exec_single_context
    self.dialect.do_execute(
  File "/opt/sidney/venv/lib/python3.12/site-packages/sqlalchemy/engine/default.py", line 921, in do_execute
    cursor.execute(statement, parameters)
sqlalchemy.exc.OperationalError: (sqlite3.OperationalError) no such table: web_users
[SQL: SELECT web_users.id AS web_users_id, web_users.username AS web_users_username, web_users.password_hash AS web_users_password_hash, web_users.email AS web_users_email, web_users.is_admin AS web_users_is_admin, web_users.last_login AS web_users_last_login, web_users.created_at AS web_users_created_at 
FROM web_users 
WHERE web_users.id = ?]
[parameters: (1,)]
(Background on this error at: https://sqlalche.me/e/20/e3q8)
2025-05-05 12:12:35,773 ERROR: Server Error: 500 Internal Server Error: The server encountered an internal error and was unable to complete your request. Either the server is overloaded or there is an error in the application. [in /opt/sidney/app/errors.py:10]
2025-05-05 12:13:20,850 INFO: Sidney starting up [in /opt/sidney/app/__init__.py:33]
2025-05-05 12:13:23,666 INFO: Sidney starting up [in /opt/sidney/app/__init__.py:33]
2025-05-05 12:13:33,450 ERROR: Error running predefined query: no such column: last_seen [in /opt/sidney/app/routes/queries.py:477]
2025-05-05 12:13:33,450 ERROR: Exception on /queries/predefined [POST] [in /opt/sidney/venv/lib/python3.12/site-packages/flask/app.py:1414]
Traceback (most recent call last):
  File "/opt/sidney/venv/lib/python3.12/site-packages/flask/app.py", line 2190, in wsgi_app
    response = self.full_dispatch_request()
               ^^^^^^^^^^^^^^^^^^^^^^^^^^^^
  File "/opt/sidney/venv/lib/python3.12/site-packages/flask/app.py", line 1486, in full_dispatch_request
    rv = self.handle_user_exception(e)
         ^^^^^^^^^^^^^^^^^^^^^^^^^^^^^
  File "/opt/sidney/venv/lib/python3.12/site-packages/flask/app.py", line 1484, in full_dispatch_request
    rv = self.dispatch_request()
         ^^^^^^^^^^^^^^^^^^^^^^^
  File "/opt/sidney/venv/lib/python3.12/site-packages/flask/app.py", line 1469, in dispatch_request
    return self.ensure_sync(self.view_functions[rule.endpoint])(**view_args)
           ^^^^^^^^^^^^^^^^^^^^^^^^^^^^^^^^^^^^^^^^^^^^^^^^^^^^^^^^^^^^^^^^^
  File "/opt/sidney/venv/lib/python3.12/site-packages/flask_login/utils.py", line 290, in decorated_view
    return current_app.ensure_sync(func)(*args, **kwargs)
           ^^^^^^^^^^^^^^^^^^^^^^^^^^^^^^^^^^^^^^^^^^^^^^
  File "/opt/sidney/app/routes/queries.py", line 63, in predefined
    results = run_predefined_query(query_name, params)
              ^^^^^^^^^^^^^^^^^^^^^^^^^^^^^^^^^^^^^^^^
  File "/opt/sidney/app/routes/queries.py", line 467, in run_predefined_query
    cursor.execute(query['sql'], query['params'])
sqlite3.OperationalError: no such column: last_seen
2025-05-05 12:13:33,451 ERROR: Server Error: 500 Internal Server Error: The server encountered an internal error and was unable to complete your request. Either the server is overloaded or there is an error in the application. [in /opt/sidney/app/errors.py:10]
2025-05-05 12:15:05,121 INFO: Sidney starting up [in /opt/sidney/app/__init__.py:33]
2025-05-05 12:15:11,703 INFO: Sidney starting up [in /opt/sidney/app/__init__.py:33]
2025-05-05 12:15:15,155 ERROR: Error getting database stats: no such table: hosts [in /opt/sidney/app/routes/dashboard.py:109]
2025-05-05 12:15:15,155 ERROR: Error getting chart data: no such table: scan_sessions [in /opt/sidney/app/routes/dashboard.py:204]
2025-05-05 12:15:41,373 ERROR: Error running predefined query: no such column: last_seen [in /opt/sidney/app/routes/queries.py:477]
