2025-05-05 12:03:40,525 ERROR: Exception on /queries/predefined [POST] [in /opt/sidney/venv/lib/python3.12/site-packages/flask/app.py:1414]
Traceback (most recent call last):
  File "/opt/sidney/venv/lib/python3.12/site-packages/flask/app.py", line 2190, in wsgi_app
    response = self.full_dispatch_request()
               ^^^^^^^^^^^^^^^^^^^^^^^^^^^^
  File "/opt/sidney/venv/lib/python3.12/site-packages/flask/app.py", line 1486, in full_dispatch_request
    rv = self.handle_user_exception(e)
         ^^^^^^^^^^^^^^^^^^^^^^^^^^^^^
  File "/opt/sidney/venv/lib/python3.12/site-packages/flask/app.py", line 1484, in full_dispatch_request
    rv = self.dispatch_request()
         ^^^^^^^^^^^^^^^^^^^^^^^
  File "/opt/sidney/venv/lib/python3.12/site-packages/flask/app.py", line 1469, in dispatch_request
    return self.ensure_sync(self.view_functions[rule.endpoint])(**view_args)
           ^^^^^^^^^^^^^^^^^^^^^^^^^^^^^^^^^^^^^^^^^^^^^^^^^^^^^^^^^^^^^^^^^
  File "/opt/sidney/venv/lib/python3.12/site-packages/flask_login/utils.py", line 290, in decorated_view
    return current_app.ensure_sync(func)(*args, **kwargs)
           ^^^^^^^^^^^^^^^^^^^^^^^^^^^^^^^^^^^^^^^^^^^^^^
  File "/opt/sidney/app/routes/queries.py", line 63, in predefined
    results = run_predefined_query(query_name, params)
              ^^^^^^^^^^^^^^^^^^^^^^^^^^^^^^^^^^^^^^^^
  File "/opt/sidney/app/routes/queries.py", line 467, in run_predefined_query
    cursor.execute(query['sql'], query['params'])
sqlite3.OperationalError: no such table: hosts
2025-05-05 12:03:40,527 ERROR: Server Error: 500 Internal Server Error: The server encountered an internal error and was unable to complete your request. Either the server is overloaded or there is an error in the application. [in /opt/sidney/app/errors.py:10]
2025-05-05 12:03:50,862 ERROR: Error getting database stats: no such table: hosts [in /opt/sidney/app/routes/dashboard.py:109]
2025-05-05 12:03:50,863 ERROR: Error getting chart data: no such table: scan_sessions [in /opt/sidney/app/routes/dashboard.py:204]
2025-05-05 12:05:28,688 ERROR: Error running predefined query: no such column: last_seen [in /opt/sidney/app/routes/queries.py:477]
2025-05-05 12:05:28,688 ERROR: Exception on /queries/predefined [POST] [in /opt/sidney/venv/lib/python3.12/site-packages/flask/app.py:1414]
Traceback (most recent call last):
  File "/opt/sidney/venv/lib/python3.12/site-packages/flask/app.py", line 2190, in wsgi_app
    response = self.full_dispatch_request()
               ^^^^^^^^^^^^^^^^^^^^^^^^^^^^
  File "/opt/sidney/venv/lib/python3.12/site-packages/flask/app.py", line 1486, in full_dispatch_request
    rv = self.handle_user_exception(e)
         ^^^^^^^^^^^^^^^^^^^^^^^^^^^^^
  File "/opt/sidney/venv/lib/python3.12/site-packages/flask/app.py", line 1484, in full_dispatch_request
    rv = self.dispatch_request()
         ^^^^^^^^^^^^^^^^^^^^^^^
  File "/opt/sidney/venv/lib/python3.12/site-packages/flask/app.py", line 1469, in dispatch_request
    return self.ensure_sync(self.view_functions[rule.endpoint])(**view_args)
           ^^^^^^^^^^^^^^^^^^^^^^^^^^^^^^^^^^^^^^^^^^^^^^^^^^^^^^^^^^^^^^^^^
  File "/opt/sidney/venv/lib/python3.12/site-packages/flask_login/utils.py", line 290, in decorated_view
    return current_app.ensure_sync(func)(*args, **kwargs)
           ^^^^^^^^^^^^^^^^^^^^^^^^^^^^^^^^^^^^^^^^^^^^^^
  File "/opt/sidney/app/routes/queries.py", line 63, in predefined
    results = run_predefined_query(query_name, params)
              ^^^^^^^^^^^^^^^^^^^^^^^^^^^^^^^^^^^^^^^^
  File "/opt/sidney/app/routes/queries.py", line 467, in run_predefined_query
    cursor.execute(query['sql'], query['params'])
sqlite3.OperationalError: no such column: last_seen
2025-05-05 12:05:28,689 ERROR: Server Error: 500 Internal Server Error: The server encountered an internal error and was unable to complete your request. Either the server is overloaded or there is an error in the application. [in /opt/sidney/app/errors.py:10]
2025-05-05 12:08:44,471 INFO: Sidney starting up [in /opt/sidney/app/__init__.py:33]
2025-05-05 12:12:31,989 INFO: Sidney starting up [in /opt/sidney/app/__init__.py:33]
2025-05-05 12:12:33,703 ERROR: Exception on / [GET] [in /opt/sidney/venv/lib/python3.12/site-packages/flask/app.py:1414]
Traceback (most recent call last):
  File "/opt/sidney/venv/lib/python3.12/site-packages/sqlalchemy/engine/base.py", line 1965, in _exec_single_context
    self.dialect.do_execute(
  File "/opt/sidney/venv/lib/python3.12/site-packages/sqlalchemy/engine/default.py", line 921, in do_execute
    cursor.execute(statement, parameters)
sqlite3.OperationalError: no such table: web_users

The above exception was the direct cause of the following exception:

Traceback (most recent call last):
  File "/opt/sidney/venv/lib/python3.12/site-packages/flask/app.py", line 2190, in wsgi_app
    response = self.full_dispatch_request()
               ^^^^^^^^^^^^^^^^^^^^^^^^^^^^
  File "/opt/sidney/venv/lib/python3.12/site-packages/flask/app.py", line 1486, in full_dispatch_request
    rv = self.handle_user_exception(e)
         ^^^^^^^^^^^^^^^^^^^^^^^^^^^^^
  File "/opt/sidney/venv/lib/python3.12/site-packages/flask/app.py", line 1484, in full_dispatch_request
    rv = self.dispatch_request()
         ^^^^^^^^^^^^^^^^^^^^^^^
  File "/opt/sidney/venv/lib/python3.12/site-packages/flask/app.py", line 1469, in dispatch_request
    return self.ensure_sync(self.view_functions[rule.endpoint])(**view_args)
           ^^^^^^^^^^^^^^^^^^^^^^^^^^^^^^^^^^^^^^^^^^^^^^^^^^^^^^^^^^^^^^^^^
  File "/opt/sidney/app/routes/main.py", line 14, in index
    if current_user.is_authenticated:
       ^^^^^^^^^^^^^^^^^^^^^^^^^^^^^
  File "/opt/sidney/venv/lib/python3.12/site-packages/werkzeug/local.py", line 311, in __get__
    obj = instance._get_current_object()
          ^^^^^^^^^^^^^^^^^^^^^^^^^^^^^^
  File "/opt/sidney/venv/lib/python3.12/site-packages/werkzeug/local.py", line 515, in _get_current_object
    return get_name(local())
                    ^^^^^^^
  File "/opt/sidney/venv/lib/python3.12/site-packages/flask_login/utils.py", line 25, in <lambda>
    current_user = LocalProxy(lambda: _get_user())
                                      ^^^^^^^^^^^
  File "/opt/sidney/venv/lib/python3.12/site-packages/flask_login/utils.py", line 372, in _get_user
    current_app.login_manager._load_user()
  File "/opt/sidney/venv/lib/python3.12/site-packages/flask_login/login_manager.py", line 364, in _load_user
    user = self._user_callback(user_id)
           ^^^^^^^^^^^^^^^^^^^^^^^^^^^^
  File "/opt/sidney/app/__init__.py", line 50, in load_user
    return User.query.get(int(user_id))
           ^^^^^^^^^^^^^^^^^^^^^^^^^^^^
  File "<string>", line 2, in get
  File "/opt/sidney/venv/lib/python3.12/site-packages/sqlalchemy/util/deprecations.py", line 386, in warned
    return fn(*args, **kwargs)  # type: ignore[no-any-return]
           ^^^^^^^^^^^^^^^^^^^
  File "/opt/sidney/venv/lib/python3.12/site-packages/sqlalchemy/orm/query.py", line 1131, in get
    return self._get_impl(ident, loading.load_on_pk_identity)
           ^^^^^^^^^^^^^^^^^^^^^^^^^^^^^^^^^^^^^^^^^^^^^^^^^^
  File "/opt/sidney/venv/lib/python3.12/site-packages/sqlalchemy/orm/query.py", line 1140, in _get_impl
    return self.session._get_impl(
           ^^^^^^^^^^^^^^^^^^^^^^^
  File "/opt/sidney/venv/lib/python3.12/site-packages/sqlalchemy/orm/session.py", line 3700, in _get_impl
    return db_load_fn(
           ^^^^^^^^^^^
  File "/opt/sidney/venv/lib/python3.12/site-packages/sqlalchemy/orm/loading.py", line 666, in load_on_pk_identity
    session.execute(
  File "/opt/sidney/venv/lib/python3.12/site-packages/sqlalchemy/orm/session.py", line 2262, in execute
    return self._execute_internal(
           ^^^^^^^^^^^^^^^^^^^^^^^
  File "/opt/sidney/venv/lib/python3.12/site-packages/sqlalchemy/orm/session.py", line 2144, in _execute_internal
    result: Result[Any] = compile_state_cls.orm_execute_statement(
                          ^^^^^^^^^^^^^^^^^^^^^^^^^^^^^^^^^^^^^^^^
  File "/opt/sidney/venv/lib/python3.12/site-packages/sqlalchemy/orm/context.py", line 293, in orm_execute_statement
    result = conn.execute(
             ^^^^^^^^^^^^^
  File "/opt/sidney/venv/lib/python3.12/site-packages/sqlalchemy/engine/base.py", line 1412, in execute
    return meth(
           ^^^^^
  File "/opt/sidney/venv/lib/python3.12/site-packages/sqlalchemy/sql/elements.py", line 515, in _execute_on_connection
    return connection._execute_clauseelement(
           ^^^^^^^^^^^^^^^^^^^^^^^^^^^^^^^^^^
  File "/opt/sidney/venv/lib/python3.12/site-packages/sqlalchemy/engine/base.py", line 1635, in _execute_clauseelement
    ret = self._execute_context(
          ^^^^^^^^^^^^^^^^^^^^^^
  File "/opt/sidney/venv/lib/python3.12/site-packages/sqlalchemy/engine/base.py", line 1844, in _execute_context
    return self._exec_single_context(
           ^^^^^^^^^^^^^^^^^^^^^^^^^^
  File "/opt/sidney/venv/lib/python3.12/site-packages/sqlalchemy/engine/base.py", line 1984, in _exec_single_context
    self._handle_dbapi_exception(
  File "/opt/sidney/venv/lib/python3.12/site-packages/sqlalchemy/engine/base.py", line 2339, in _handle_dbapi_exception
    raise sqlalchemy_exception.with_traceback(exc_info[2]) from e
  File "/opt/sidney/venv/lib/python3.12/site-packages/sqlalchemy/engine/base.py", line 1965, in _exec_single_context
    self.dialect.do_execute(
  File "/opt/sidney/venv/lib/python3.12/site-packages/sqlalchemy/engine/default.py", line 921, in do_execute
    cursor.execute(statement, parameters)
sqlalchemy.exc.OperationalError: (sqlite3.OperationalError) no such table: web_users
[SQL: SELECT web_users.id AS web_users_id, web_users.username AS web_users_username, web_users.password_hash AS web_users_password_hash, web_users.email AS web_users_email, web_users.is_admin AS web_users_is_admin, web_users.last_login AS web_users_last_login, web_users.created_at AS web_users_created_at 
FROM web_users 
WHERE web_users.id = ?]
[parameters: (1,)]
(Background on this error at: https://sqlalche.me/e/20/e3q8)
